Workbook
Name UPDATE: 'Data Sheet'!$E$1

Sheet Financials>

Sheet HistoricalFS
B2: ="Historical Financial Statement - "&'Data Sheet'!B1 -> Historical Financial Statement - INFOSYS LTD
B3: Years | C3: ='Data Sheet'!B16 -> 42460 | D3: ='Data Sheet'!C16 -> 42825 | E3: ='Data Sheet'!D16 -> 43190 | F3: ='Data Sheet'!E16 -> 43555 | G3: ='Data Sheet'!F16 -> 43921 | H3: ='Data Sheet'!G16 -> 44286 | I3: ='Data Sheet'!H16 -> 44651 | J3: ='Data Sheet'!I16 -> 45016 | ... L3: ='Data Sheet'!K16 -> 45747
A5: # | B5: Income Statement
B6: Sales | C6: =IFERROR('Data Sheet'!B17,0) -> 62441 | D6: =IFERROR('Data Sheet'!C17,0) -> 68484 | E6: =IFERROR('Data Sheet'!D17,0) -> 70522 | F6: =IFERROR('Data Sheet'!E17,0) -> 82675 | G6: =IFERROR('Data Sheet'!F17,0) -> 90791 | H6: =IFERROR('Data Sheet'!G17,0) -> 100472 | I6: =IFERROR('Data Sheet'!H17,0) -> 121641 | J6: =IFERROR('Data Sheet'!I17,0) -> 146767 | ... L6: =IFERROR('Data Sheet'!K17,0) -> 162990
B7: Sales Growth | C7: - | D7: =D6/C6-1 -> 0.09677936 | E7: =E6/D6-1 -> 0.029758776 | F7: =F6/E6-1 -> 0.1723292 | G7: =G6/F6-1 -> 0.098167523 | H7: =H6/G6-1 -> 0.10662951 | I7: =I6/H6-1 -> 0.21069552 | J7: =J6/I6-1 -> 0.20655864 | K7: =K6/J6-1 -> 0.047033734 | L7: =L6/K6-1 -> 0.060649444
B9: COGS | C9: {=IFERROR(SUM('Data Sheet'!B20:B22-1*'Data Sheet'!B19),0)} -> 40492 | D9: {=IFERROR(SUM('Data Sheet'!C20:C22-1*'Data Sheet'!C19),0)} -> 44609 | E9: {=IFERROR(SUM('Data Sheet'!D20:D22-1*'Data Sheet'!D19),0)} -> 46395 | F9: {=IFERROR(SUM('Data Sheet'!E20:E22-1*'Data Sheet'!E19),0)} -> 55446 | G9: {=IFERROR(SUM('Data Sheet'!F20:F22-1*'Data Sheet'!F19),0)} -> 62210 | H9: {=IFERROR(SUM('Data Sheet'!G20:G22-1*'Data Sheet'!G19),0)} -> 68490 | I9: {=IFERROR(SUM('Data Sheet'!H20:H22-1*'Data Sheet'!H19),0)} -> 84819 | J9: {=IFERROR(SUM('Data Sheet'!I20:I22-1*'Data Sheet'!I19),0)} -> 104880 | ... L9: {=IFERROR(SUM('Data Sheet'!K20:K22-1*'Data Sheet'!K19),0)} -> 116585
B10: COGS % Sales | C10: - | D10: =D9/C9-1 -> 0.1016744 | E10: =E9/D9-1 -> 0.040036764 | F10: =F9/E9-1 -> 0.19508568 | G10: =G9/F9-1 -> 0.12199257 | H10: =H9/G9-1 -> 0.1009484 | I10: =I9/H9-1 -> 0.23841437 | J10: =J9/I9-1 -> 0.2365154 | K10: =K9/J9-1 -> 0.049103738 | L10: =L9/K9-1 -> 0.059574661
B12: Gross Profit | C12: =IFERROR(C6-C9,0) -> 21949 | D12: =IFERROR(D6-D9,0) -> 23875 | E12: =IFERROR(E6-E9,0) -> 24127 | F12: =IFERROR(F6-F9,0) -> 27229 | G12: =IFERROR(G6-G9,0) -> 28581 | H12: =IFERROR(H6-H9,0) -> 31982 | I12: =IFERROR(I6-I9,0) -> 36822 | J12: =IFERROR(J6-J9,0) -> 41887 | ... L12: =IFERROR(L6-L9,0) -> 46405
B13: Gross Profit Margins | C13: =C12/C6 -> 0.35151583 | D13: =D12/D6 -> 0.34862158 | E13: =E12/E6 -> 0.34212019 | F13: =F12/F6 -> 0.32934986 | G13: =G12/G6 -> 0.31479993 | H13: =H12/H6 -> 0.31831754 | I13: =I12/I6 -> 0.30271043 | J13: =J12/J6 -> 0.28539794 | ... L13: =L12/L6 -> 0.28471072
B15: Selling & General Expenses | C15: =IFERROR(SUM('Data Sheet'!B23:B24),0) -> 4870 | D15: =IFERROR(SUM('Data Sheet'!C23:C24),0) -> 5271 | E15: =IFERROR(SUM('Data Sheet'!D23:D24),0) -> 5305 | F15: =IFERROR(SUM('Data Sheet'!E23:E24),0) -> 7059 | G15: =IFERROR(SUM('Data Sheet'!F23:F24),0) -> 6314 | H15: =IFERROR(SUM('Data Sheet'!G23:G24),0) -> 4093 | I15: =IFERROR(SUM('Data Sheet'!H23:H24),0) -> 5331 | J15: =IFERROR(SUM('Data Sheet'!I23:I24),0) -> 6757 | ... L15: =IFERROR(SUM('Data Sheet'!K23:K24),0) -> 7169
B16: S&G Expenses % Sales | C16: =C15/C6 -> 0.077993626 | D16: =D15/D6 -> 0.076966883 | E16: =E15/E6 -> 0.075224753 | F16: =F15/F6 -> 0.085382522 | G16: =G15/G6 -> 0.069544338 | H16: =H15/H6 -> 0.040737718 | I16: =I15/I6 -> 0.043825684 | J16: =J15/J6 -> 0.04603896 | ... L16: =L15/L6 -> 0.043984294
B18: EBITDA | C18: =IFERROR(C12-C15,0) -> 17079 | D18: =IFERROR(D12-D15,0) -> 18604 | E18: =IFERROR(E12-E15,0) -> 18822 | F18: =IFERROR(F12-F15,0) -> 20170 | G18: =IFERROR(G12-G15,0) -> 22267 | H18: =IFERROR(H12-H15,0) -> 27889 | I18: =IFERROR(I12-I15,0) -> 31491 | J18: =IFERROR(J12-J15,0) -> 35130 | ... L18: =IFERROR(L12-L15,0) -> 39236
B19: EBITDA Margins | C19: =IFERROR(C18/C6,0) -> 0.2735222 | D19: =IFERROR(D18/D6,0) -> 0.27165469 | E19: =IFERROR(E18/E6,0) -> 0.26689544 | F19: =IFERROR(F18/F6,0) -> 0.24396734 | G19: =IFERROR(G18/G6,0) -> 0.24525559 | H19: =IFERROR(H18/H6,0) -> 0.27757982 | I19: =IFERROR(I18/I6,0) -> 0.25888475 | J19: =IFERROR(J18/J6,0) -> 0.23935898 | ... L19: =IFERROR(L18/L6,0) -> 0.24072642
B21: Interest | C21: =IFERROR('Data Sheet'!B27,0) -> 0 | D21: =IFERROR('Data Sheet'!C27,0) -> 0 | E21: =IFERROR('Data Sheet'!D27,0) -> 0 | F21: =IFERROR('Data Sheet'!E27,0) -> 0 | G21: =IFERROR('Data Sheet'!F27,0) -> 170 | H21: =IFERROR('Data Sheet'!G27,0) -> 195 | I21: =IFERROR('Data Sheet'!H27,0) -> 200 | J21: =IFERROR('Data Sheet'!I27,0) -> 284 | ... L21: =IFERROR('Data Sheet'!K27,0) -> 416
B22: Interest % Sales | C22: =IFERROR(C21/C6,0) -> 0 | D22: =IFERROR(D21/D6,0) -> 0 | E22: =IFERROR(E21/E6,0) -> 0 | F22: =IFERROR(F21/F6,0) -> 0 | G22: =IFERROR(G21/G6,0) -> 0.0018724323 | H22: =IFERROR(H21/H6,0) -> 0.0019408392 | I22: =IFERROR(I21/I6,0) -> 0.0016441825 | J22: =IFERROR(J21/J6,0) -> 0.0019350399 | ... L22: =IFERROR(L21/L6,0) -> 0.0025523038
B24: Depreciation | C24: =IFERROR('Data Sheet'!B26,0) -> 1459 | D24: =IFERROR('Data Sheet'!C26,0) -> 1703 | E24: =IFERROR('Data Sheet'!D26,0) -> 1863 | F24: =IFERROR('Data Sheet'!E26,0) -> 2011 | G24: =IFERROR('Data Sheet'!F26,0) -> 2893 | H24: =IFERROR('Data Sheet'!G26,0) -> 3267 | I24: =IFERROR('Data Sheet'!H26,0) -> 3476 | J24: =IFERROR('Data Sheet'!I26,0) -> 4225 | ... L24: =IFERROR('Data Sheet'!K26,0) -> 4812
B25: Depreciation % Sales | C25: =IFERROR(C24/C6,0) -> 0.023366058 | D25: =IFERROR(D24/D6,0) -> 0.024867122 | E25: =IFERROR(E24/E6,0) -> 0.026417288 | F25: =IFERROR(F24/F6,0) -> 0.024324161 | G25: =IFERROR(G24/G6,0) -> 0.031864392 | H25: =IFERROR(H24/H6,0) -> 0.032516522 | I25: =IFERROR(I24/I6,0) -> 0.028575891 | J25: =IFERROR(J24/J6,0) -> 0.028787125 | ... L25: =IFERROR(L24/L6,0) -> 0.029523284
B27: EBT | C27: =IFERROR(C18-SUM(C24,C21),0) -> 15620 | D27: =IFERROR(D18-SUM(D24,D21),0) -> 16901 | E27: =IFERROR(E18-SUM(E24,E21),0) -> 16959 | F27: =IFERROR(F18-SUM(F24,F21),0) -> 18159 | G27: =IFERROR(G18-SUM(G24,G21),0) -> 19204 | H27: =IFERROR(H18-SUM(H24,H21),0) -> 24427 | I27: =IFERROR(I18-SUM(I24,I21),0) -> 27815 | J27: =IFERROR(J18-SUM(J24,J21),0) -> 30621 | ... L27: =IFERROR(L18-SUM(L24,L21),0) -> 34008
B28: EBT % Sales | C28: =IFERROR(C27/C6,0) -> 0.25015615 | D28: =IFERROR(D27/D6,0) -> 0.24678757 | E28: =IFERROR(E27/E6,0) -> 0.24047815 | F28: =IFERROR(F27/F6,0) -> 0.21964318 | G28: =IFERROR(G27/G6,0) -> 0.21151876 | H28: =IFERROR(H27/H6,0) -> 0.24312246 | I28: =IFERROR(I27/I6,0) -> 0.22866468 | J28: =IFERROR(J27/J6,0) -> 0.20863682 | ... L28: =IFERROR(L27/L6,0) -> 0.20865084
B30: Tax | C30: =IFERROR('Data Sheet'!B29,0) -> 5251 | D30: =IFERROR('Data Sheet'!C29,0) -> 5598 | E30: =IFERROR('Data Sheet'!D29,0) -> 4241 | F30: =IFERROR('Data Sheet'!E29,0) -> 5631 | G30: =IFERROR('Data Sheet'!F29,0) -> 5368 | H30: =IFERROR('Data Sheet'!G29,0) -> 7205 | I30: =IFERROR('Data Sheet'!H29,0) -> 7964 | J30: =IFERROR('Data Sheet'!I29,0) -> 9214 | ... L30: =IFERROR('Data Sheet'!K29,0) -> 10858
B31: Effective Tax Rate | C31: =IFERROR(C30/C27,0) -> 0.33617157 | D31: =IFERROR(D30/D27,0) -> 0.331223 | E31: =IFERROR(E30/E27,0) -> 0.25007371 | F31: =IFERROR(F30/F27,0) -> 0.31009417 | G31: =IFERROR(G30/G27,0) -> 0.2795251 | H31: =IFERROR(H30/H27,0) -> 0.29496049 | I31: =IFERROR(I30/I27,0) -> 0.28632033 | J31: =IFERROR(J30/J27,0) -> 0.30090461 | ... L31: =IFERROR(L30/L27,0) -> 0.31927782
B33: Net Profit | C33: =IFERROR(C27-C30,0) -> 10369 | D33: =IFERROR(D27-D30,0) -> 11303 | E33: =IFERROR(E27-E30,0) -> 12718 | F33: =IFERROR(F27-F30,0) -> 12528 | G33: =IFERROR(G27-G30,0) -> 13836 | H33: =IFERROR(H27-H30,0) -> 17222 | I33: =IFERROR(I27-I30,0) -> 19851 | J33: =IFERROR(J27-J30,0) -> 21407 | ... L33: =IFERROR(L27-L30,0) -> 23150
B34: Net Margins | C34: =IFERROR(C33/C6,0) -> 0.16606076 | D34: =IFERROR(D33/D6,0) -> 0.16504585 | E34: =IFERROR(E33/E6,0) -> 0.18034089 | F34: =IFERROR(F33/F6,0) -> 0.15153311 | G34: =IFERROR(G33/G6,0) -> 0.15239396 | H34: =IFERROR(H33/H6,0) -> 0.17141094 | I34: =IFERROR(I33/I6,0) -> 0.16319333 | J34: =IFERROR(J33/J6,0) -> 0.14585704 | ... L34: =IFERROR(L33/L6,0) -> 0.14203325
B36: No. of Equity Shares | C36: =IFERROR('Data Sheet'!B95,0) -> 459.39 | D36: =IFERROR('Data Sheet'!C95,0) -> 459.39 | E36: =IFERROR('Data Sheet'!D95,0) -> 436.82 | F36: =IFERROR('Data Sheet'!E95,0) -> 436.89 | G36: =IFERROR('Data Sheet'!F95,0) -> 425.9 | H36: =IFERROR('Data Sheet'!G95,0) -> 426.07 | I36: =IFERROR('Data Sheet'!H95,0) -> 420.67 | J36: =IFERROR('Data Sheet'!I95,0) -> 414.86 | ... L36: =IFERROR('Data Sheet'!K95,0) -> 415.33
B38: EPS | C38: =IFERROR(C33/C36,0) -> 22.571236 | D38: =IFERROR(D33/D36,0) -> 24.604367 | E38: =IFERROR(E33/E36,0) -> 29.114967 | F38: =IFERROR(F33/F36,0) -> 28.67541 | G38: =IFERROR(G33/G36,0) -> 32.486499 | H38: =IFERROR(H33/H36,0) -> 40.420588 | I38: =IFERROR(I33/I36,0) -> 47.189008 | J38: =IFERROR(J33/J36,0) -> 51.60054 | ... L38: =IFERROR(L33/L36,0) -> 55.73881
B39: EPS Growth % | D39: =IFERROR(D38/C38-1,0) -> 0.090076189 | E39: =IFERROR(E38/D38-1,0) -> 0.18332521 | F39: =IFERROR(F38/E38-1,0) -> -0.015097286 | G39: =IFERROR(G38/F38-1,0) -> 0.13290442 | H39: =IFERROR(H38/G38-1,0) -> 0.24422727 | I39: =IFERROR(I38/H38-1,0) -> 0.16744981 | J39: =IFERROR(J38/I38-1,0) -> 0.093486431 | K39: =IFERROR(K38/J38-1,0) -> 0.0055153183 | L39: =IFERROR(L38/K38-1,0) -> 0.074273236
B41: Divident Per Share | C41: =IFERROR('Data Sheet'!B31/HistoricalFS!C36,0) -> 12.077755 | D41: =IFERROR('Data Sheet'!C31/HistoricalFS!D36,0) -> 12.824833 | E41: =IFERROR('Data Sheet'!D31/HistoricalFS!E36,0) -> 21.669337 | F41: =IFERROR('Data Sheet'!E31/HistoricalFS!F36,0) -> 21.109433 | G41: =IFERROR('Data Sheet'!F31/HistoricalFS!G36,0) -> 17.438366 | H41: =IFERROR('Data Sheet'!G31/HistoricalFS!H36,0) -> 26.91952 | I41: =IFERROR('Data Sheet'!H31/HistoricalFS!I36,0) -> 30.92115 | J41: =IFERROR('Data Sheet'!I31/HistoricalFS!J36,0) -> 33.913127 | ... L41: =IFERROR('Data Sheet'!K31/HistoricalFS!L36,0) -> 42.924422
B42: Divident Payout Ratio | C42: =IFERROR(C41/C38,0) -> 0.53509499 | D42: =IFERROR(D41/D38,0) -> 0.52124215 | E42: =IFERROR(E41/E38,0) -> 0.74426797 | F42: =IFERROR(F41/F38,0) -> 0.73615102 | G42: =IFERROR(G41/G38,0) -> 0.53678809 | H42: =IFERROR(H41/H38,0) -> 0.66598537 | I42: =IFERROR(I41/I38,0) -> 0.6552617 | J42: =IFERROR(J41/J38,0) -> 0.65722427 | ... L42: =IFERROR(L41/L38,0) -> 0.77009935
B44: Retained Earnings | C44: =IFERROR(IF(C38>C41,1-C42,0),0) -> 0.46490501 | D44: =IFERROR(IF(D38>D41,1-D42,0),0) -> 0.47875785 | E44: =IFERROR(IF(E38>E41,1-E42,0),0) -> 0.25573203 | F44: =IFERROR(IF(F38>F41,1-F42,0),0) -> 0.26384898 | G44: =IFERROR(IF(G38>G41,1-G42,0),0) -> 0.46321191 | H44: =IFERROR(IF(H38>H41,1-H42,0),0) -> 0.33401463 | I44: =IFERROR(IF(I38>I41,1-I42,0),0) -> 0.3447383 | J44: =IFERROR(IF(J38>J41,1-J42,0),0) -> 0.34277573 | ... L44: =IFERROR(IF(L38>L41,1-L42,0),0) -> 0.22990065
A46: # | B46: Balance Sheet
B47: Equity Share Capital | C47: =IFERROR('Data Sheet'!B57,0) -> 1144 | D47: =IFERROR('Data Sheet'!C57,0) -> 1144 | E47: =IFERROR('Data Sheet'!D57,0) -> 1088 | F47: =IFERROR('Data Sheet'!E57,0) -> 2170 | G47: =IFERROR('Data Sheet'!F57,0) -> 2122 | H47: =IFERROR('Data Sheet'!G57,0) -> 2124 | I47: =IFERROR('Data Sheet'!H57,0) -> 2098 | J47: =IFERROR('Data Sheet'!I57,0) -> 2069 | ... L47: =IFERROR('Data Sheet'!K57,0) -> 2073
B48: Reserves | C48: =IFERROR('Data Sheet'!B58,0) -> 60600 | D48: =IFERROR('Data Sheet'!C58,0) -> 67838 | E48: =IFERROR('Data Sheet'!D58,0) -> 63835 | F48: =IFERROR('Data Sheet'!E58,0) -> 62778 | G48: =IFERROR('Data Sheet'!F58,0) -> 63328 | H48: =IFERROR('Data Sheet'!G58,0) -> 74227 | I48: =IFERROR('Data Sheet'!H58,0) -> 73252 | J48: =IFERROR('Data Sheet'!I58,0) -> 73338 | ... L48: =IFERROR('Data Sheet'!K58,0) -> 93745
B49: Borrowings | C49: =IFERROR('Data Sheet'!B59,0) -> 0 | D49: =IFERROR('Data Sheet'!C59,0) -> 0 | E49: =IFERROR('Data Sheet'!D59,0) -> 0 | F49: =IFERROR('Data Sheet'!E59,0) -> 0 | G49: =IFERROR('Data Sheet'!F59,0) -> 4633 | H49: =IFERROR('Data Sheet'!G59,0) -> 5325 | I49: =IFERROR('Data Sheet'!H59,0) -> 5474 | J49: =IFERROR('Data Sheet'!I59,0) -> 8299 | ... L49: =IFERROR('Data Sheet'!K59,0) -> 8227
B50: Other Liabilities | C50: =IFERROR('Data Sheet'!B60,0) -> 13354 | D50: =IFERROR('Data Sheet'!C60,0) -> 14166 | E50: =IFERROR('Data Sheet'!D60,0) -> 14426 | F50: =IFERROR('Data Sheet'!E60,0) -> 19118 | G50: =IFERROR('Data Sheet'!F60,0) -> 21717 | H50: =IFERROR('Data Sheet'!G60,0) -> 25835 | I50: =IFERROR('Data Sheet'!H60,0) -> 35905 | J50: =IFERROR('Data Sheet'!I60,0) -> 40890 | ... L50: =IFERROR('Data Sheet'!K60,0) -> 43750
B51: Total Liabilities | C51: =IFERROR('Data Sheet'!B61,0) -> 75098 | D51: =IFERROR('Data Sheet'!C61,0) -> 83148 | E51: =IFERROR('Data Sheet'!D61,0) -> 79349 | F51: =IFERROR('Data Sheet'!E61,0) -> 84066 | G51: =IFERROR('Data Sheet'!F61,0) -> 91800 | H51: =IFERROR('Data Sheet'!G61,0) -> 107511 | I51: =IFERROR('Data Sheet'!H61,0) -> 116729 | J51: =IFERROR('Data Sheet'!I61,0) -> 124596 | ... L51: =IFERROR('Data Sheet'!K61,0) -> 147795
B53: Fixed Assets Net Block | C53: =IFERROR('Data Sheet'!B62,0) -> 13386 | D53: =IFERROR('Data Sheet'!C62,0) -> 14179 | E53: =IFERROR('Data Sheet'!D62,0) -> 12574 | F53: =IFERROR('Data Sheet'!E62,0) -> 15710 | G53: =IFERROR('Data Sheet'!F62,0) -> 23789 | H53: =IFERROR('Data Sheet'!G62,0) -> 25505 | I53: =IFERROR('Data Sheet'!H62,0) -> 25800 | J53: =IFERROR('Data Sheet'!I62,0) -> 29225 | ... L53: =IFERROR('Data Sheet'!K62,0) -> 30961
B54: Capital Work in Progress | C54: =IFERROR('Data Sheet'!B63,0) -> 960 | D54: =IFERROR('Data Sheet'!C63,0) -> 1365 | E54: =IFERROR('Data Sheet'!D63,0) -> 1606 | F54: =IFERROR('Data Sheet'!E63,0) -> 1388 | G54: =IFERROR('Data Sheet'!F63,0) -> 954 | H54: =IFERROR('Data Sheet'!G63,0) -> 922 | I54: =IFERROR('Data Sheet'!H63,0) -> 416 | J54: =IFERROR('Data Sheet'!I63,0) -> 288 | ... L54: =IFERROR('Data Sheet'!K63,0) -> 814
B55: Investments | C55: =IFERROR('Data Sheet'!B64,0) -> 1892 | D55: =IFERROR('Data Sheet'!C64,0) -> 16423 | E55: =IFERROR('Data Sheet'!D64,0) -> 12163 | F55: =IFERROR('Data Sheet'!E64,0) -> 11261 | G55: =IFERROR('Data Sheet'!F64,0) -> 8792 | H55: =IFERROR('Data Sheet'!G64,0) -> 14205 | I55: =IFERROR('Data Sheet'!H64,0) -> 20324 | J55: =IFERROR('Data Sheet'!I64,0) -> 19478 | ... L55: =IFERROR('Data Sheet'!K64,0) -> 23541
B56: Other Assets | C56: =IFERROR('Data Sheet'!B65-SUM('Data Sheet'!B67:B69),0) -> 14833 | D56: =IFERROR('Data Sheet'!C65-SUM('Data Sheet'!C67:C69),0) -> 16234 | E56: =IFERROR('Data Sheet'!D65-SUM('Data Sheet'!D67:D69),0) -> 20046 | F56: =IFERROR('Data Sheet'!E65-SUM('Data Sheet'!E67:E69),0) -> 21312 | G56: =IFERROR('Data Sheet'!F65-SUM('Data Sheet'!F67:F69),0) -> 21129 | H56: =IFERROR('Data Sheet'!G65-SUM('Data Sheet'!G67:G69),0) -> 22871 | I56: =IFERROR('Data Sheet'!H65-SUM('Data Sheet'!H67:H69),0) -> 30019 | J56: =IFERROR('Data Sheet'!I65-SUM('Data Sheet'!I67:I69),0) -> 38008 | ... L56: =IFERROR('Data Sheet'!K65-SUM('Data Sheet'!K67:K69),0) -> 36866
B57: Total Non Current Assets | C57: =IFERROR(SUM(C53:C56),0) -> 31071 | D57: =IFERROR(SUM(D53:D56),0) -> 48201 | E57: =IFERROR(SUM(E53:E56),0) -> 46389 | F57: =IFERROR(SUM(F53:F56),0) -> 49671 | G57: =IFERROR(SUM(G53:G56),0) -> 54664 | H57: =IFERROR(SUM(H53:H56),0) -> 63503 | I57: =IFERROR(SUM(I53:I56),0) -> 76559 | J57: =IFERROR(SUM(J53:J56),0) -> 86999 | ... L57: =IFERROR(SUM(L53:L56),0) -> 92182
...

Sheet Ratio Analysis
B2: ="Ratio Analysis - "&'Data Sheet'!B1 -> Ratio Analysis - INFOSYS LTD
B3: Years | C3: ='Data Sheet'!B16 -> 42460 | D3: ='Data Sheet'!C16 -> 42825 | E3: ='Data Sheet'!D16 -> 43190 | F3: ='Data Sheet'!E16 -> 43555 | G3: ='Data Sheet'!F16 -> 43921 | H3: ='Data Sheet'!G16 -> 44286 | I3: ='Data Sheet'!H16 -> 44651 | J3: ='Data Sheet'!I16 -> 45016 | ... L3: ='Data Sheet'!K16 -> 45747 | M3: Trand | N3: Mean | O3: Median
B5: Sales Growth | C5: =IFERROR(HistoricalFS!C7,0) -> - | D5: =IFERROR(HistoricalFS!D7,0) -> 0.09677936 | E5: =IFERROR(HistoricalFS!E7,0) -> 0.029758776 | F5: =IFERROR(HistoricalFS!F7,0) -> 0.1723292 | G5: =IFERROR(HistoricalFS!G7,0) -> 0.098167523 | H5: =IFERROR(HistoricalFS!H7,0) -> 0.10662951 | I5: =IFERROR(HistoricalFS!I7,0) -> 0.21069552 | J5: =IFERROR(HistoricalFS!J7,0) -> 0.20655864 | ... L5: =IFERROR(HistoricalFS!L7,0) -> 0.060649444 | N5: =IFERROR(AVERAGE(D5:L5),0) -> 0.11428908 | O5: =IFERROR(MEDIAN(C5:L5),0) -> 0.098167523
B6: EBITDA Growth | D6: =IFERROR(HistoricalFS!D18/HistoricalFS!C18-1,0) -> 0.089290942 | E6: =IFERROR(HistoricalFS!E18/HistoricalFS!D18-1,0) -> 0.01171791 | F6: =IFERROR(HistoricalFS!F18/HistoricalFS!E18-1,0) -> 0.071618319 | G6: =IFERROR(HistoricalFS!G18/HistoricalFS!F18-1,0) -> 0.10396629 | H6: =IFERROR(HistoricalFS!H18/HistoricalFS!G18-1,0) -> 0.25248125 | I6: =IFERROR(HistoricalFS!I18/HistoricalFS!H18-1,0) -> 0.12915486 | J6: =IFERROR(HistoricalFS!J18/HistoricalFS!I18-1,0) -> 0.11555683 | K6: =IFERROR(HistoricalFS!K18/HistoricalFS!J18-1,0) -> 0.03686308 | L6: =IFERROR(HistoricalFS!L18/HistoricalFS!K18-1,0) -> 0.077172272 | N6: =IFERROR(AVERAGE(D6:L6),0) -> 0.098646861 | O6: =IFERROR(MEDIAN(C6:L6),0) -> 0.089290942
B7: EBIT Growth | D7: =IFERROR(HistoricalFS!D27/HistoricalFS!C27-1,0) -> 0.082010243 | E7: =IFERROR(HistoricalFS!E27/HistoricalFS!D27-1,0) -> 0.0034317496 | F7: =IFERROR(HistoricalFS!F27/HistoricalFS!E27-1,0) -> 0.070758889 | G7: =IFERROR(HistoricalFS!G27/HistoricalFS!F27-1,0) -> 0.057547222 | H7: =IFERROR(HistoricalFS!H27/HistoricalFS!G27-1,0) -> 0.27197459 | I7: =IFERROR(HistoricalFS!I27/HistoricalFS!H27-1,0) -> 0.13869898 | J7: =IFERROR(HistoricalFS!J27/HistoricalFS!I27-1,0) -> 0.10088082 | K7: =IFERROR(HistoricalFS!K27/HistoricalFS!J27-1,0) -> 0.021423206 | L7: =IFERROR(HistoricalFS!L27/HistoricalFS!K27-1,0) -> 0.087316558 | N7: =IFERROR(AVERAGE(D7:L7),0) -> 0.092671362 | O7: =IFERROR(MEDIAN(C7:L7),0) -> 0.082010243
B8: Net Profit Growth | D8: =IFERROR(HistoricalFS!D33/HistoricalFS!C33-1,0) -> 0.090076189 | E8: =IFERROR(HistoricalFS!E33/HistoricalFS!D33-1,0) -> 0.125188 | F8: =IFERROR(HistoricalFS!F33/HistoricalFS!E33-1,0) -> -0.014939456 | G8: =IFERROR(HistoricalFS!G33/HistoricalFS!F33-1,0) -> 0.10440613 | H8: =IFERROR(HistoricalFS!H33/HistoricalFS!G33-1,0) -> 0.24472391 | I8: =IFERROR(HistoricalFS!I33/HistoricalFS!H33-1,0) -> 0.15265358 | J8: =IFERROR(HistoricalFS!J33/HistoricalFS!I33-1,0) -> 0.078383961 | K8: =IFERROR(HistoricalFS!K33/HistoricalFS!J33-1,0) -> 0.0060727799 | L8: =IFERROR(HistoricalFS!L33/HistoricalFS!K33-1,0) -> 0.074894368 | N8: =IFERROR(AVERAGE(D8:L8),0) -> 0.095717718 | O8: =IFERROR(MEDIAN(C8:L8),0) -> 0.090076189
B9: Divident Growth | D9: =IFERROR(HistoricalFS!D41/HistoricalFS!C41-1,0) -> 0.06185567 | E9: =IFERROR(HistoricalFS!E41/HistoricalFS!D41-1,0) -> 0.68963897 | F9: =IFERROR(HistoricalFS!F41/HistoricalFS!E41-1,0) -> -0.02583858 | G9: =IFERROR(HistoricalFS!G41/HistoricalFS!F41-1,0) -> -0.17390646 | H9: =IFERROR(HistoricalFS!H41/HistoricalFS!G41-1,0) -> 0.54369512 | I9: =IFERROR(HistoricalFS!I41/HistoricalFS!H41-1,0) -> 0.14865158 | J9: =IFERROR(HistoricalFS!J41/HistoricalFS!I41-1,0) -> 0.096761529 | K9: =IFERROR(HistoricalFS!K41/HistoricalFS!J41-1,0) -> 0.35349861 | L9: =IFERROR(HistoricalFS!L41/HistoricalFS!K41-1,0) -> -0.064855345 | N9: =IFERROR(AVERAGE(D9:L9),0) -> 0.18105568 | O9: =IFERROR(MEDIAN(C9:L9),0) -> 0.096761529
B11: Gross Margin | C11: =IFERROR(HistoricalFS!C13,0) -> 0.35151583 | D11: =IFERROR(HistoricalFS!D13,0) -> 0.34862158 | E11: =IFERROR(HistoricalFS!E13,0) -> 0.34212019 | F11: =IFERROR(HistoricalFS!F13,0) -> 0.32934986 | G11: =IFERROR(HistoricalFS!G13,0) -> 0.31479993 | H11: =IFERROR(HistoricalFS!H13,0) -> 0.31831754 | I11: =IFERROR(HistoricalFS!I13,0) -> 0.30271043 | J11: =IFERROR(HistoricalFS!J13,0) -> 0.28539794 | ... L11: =IFERROR(HistoricalFS!L13,0) -> 0.28471072 | N11: =IFERROR(AVERAGE(C11:L11),0) -> 0.31615292 | O11: =IFERROR(MEDIAN(C11:L11),0) -> 0.31655873
B12: EBITDA Margin | C12: =IFERROR(HistoricalFS!C19,0) -> 0.2735222 | D12: =IFERROR(HistoricalFS!D19,0) -> 0.27165469 | E12: =IFERROR(HistoricalFS!E19,0) -> 0.26689544 | F12: =IFERROR(HistoricalFS!F19,0) -> 0.24396734 | G12: =IFERROR(HistoricalFS!G19,0) -> 0.24525559 | H12: =IFERROR(HistoricalFS!H19,0) -> 0.27757982 | I12: =IFERROR(HistoricalFS!I19,0) -> 0.25888475 | J12: =IFERROR(HistoricalFS!J19,0) -> 0.23935898 | ... L12: =IFERROR(HistoricalFS!L19,0) -> 0.24072642 | N12: =IFERROR(AVERAGE(C12:L12),0) -> 0.25548792 | O12: =IFERROR(MEDIAN(C12:L12),0) -> 0.25207017
B13: EBIT Margin | C13: =IFERROR((HistoricalFS!C18-HistoricalFS!C24)/HistoricalFS!C6,0) -> 0.25015615 | D13: =IFERROR((HistoricalFS!D18-HistoricalFS!D24)/HistoricalFS!D6,0) -> 0.24678757 | E13: =IFERROR((HistoricalFS!E18-HistoricalFS!E24)/HistoricalFS!E6,0) -> 0.24047815 | F13: =IFERROR((HistoricalFS!F18-HistoricalFS!F24)/HistoricalFS!F6,0) -> 0.21964318 | G13: =IFERROR((HistoricalFS!G18-HistoricalFS!G24)/HistoricalFS!G6,0) -> 0.2133912 | H13: =IFERROR((HistoricalFS!H18-HistoricalFS!H24)/HistoricalFS!H6,0) -> 0.2450633 | I13: =IFERROR((HistoricalFS!I18-HistoricalFS!I24)/HistoricalFS!I6,0) -> 0.23030886 | J13: =IFERROR((HistoricalFS!J18-HistoricalFS!J24)/HistoricalFS!J6,0) -> 0.21057186 | ... L13: =IFERROR((HistoricalFS!L18-HistoricalFS!L24)/HistoricalFS!L6,0) -> 0.21120314 | N13: =IFERROR(AVERAGE(C13:L13),0) -> 0.22741955 | O13: =IFERROR(MEDIAN(C13:L13),0) -> 0.22497602
B14: EBT Margin | C14: =IFERROR(HistoricalFS!C28,0) -> 0.25015615 | D14: =IFERROR(HistoricalFS!D28,0) -> 0.24678757 | E14: =IFERROR(HistoricalFS!E28,0) -> 0.24047815 | F14: =IFERROR(HistoricalFS!F28,0) -> 0.21964318 | G14: =IFERROR(HistoricalFS!G28,0) -> 0.21151876 | H14: =IFERROR(HistoricalFS!H28,0) -> 0.24312246 | I14: =IFERROR(HistoricalFS!I28,0) -> 0.22866468 | J14: =IFERROR(HistoricalFS!J28,0) -> 0.20863682 | ... L14: =IFERROR(HistoricalFS!L28,0) -> 0.20865084 | N14: =IFERROR(AVERAGE(C14:L14),0) -> 0.22611922 | O14: =IFERROR(MEDIAN(C14:L14),0) -> 0.22415393
B15: Net Profit Margin | C15: =IFERROR(HistoricalFS!C34,0) -> 0.16606076 | D15: =IFERROR(HistoricalFS!D34,0) -> 0.16504585 | E15: =IFERROR(HistoricalFS!E34,0) -> 0.18034089 | F15: =IFERROR(HistoricalFS!F34,0) -> 0.15153311 | G15: =IFERROR(HistoricalFS!G34,0) -> 0.15239396 | H15: =IFERROR(HistoricalFS!H34,0) -> 0.17141094 | I15: =IFERROR(HistoricalFS!I34,0) -> 0.16319333 | J15: =IFERROR(HistoricalFS!J34,0) -> 0.14585704 | ... L15: =IFERROR(HistoricalFS!L34,0) -> 0.14203325 | N15: =IFERROR(AVERAGE(C15:L15),0) -> 0.15780201 | O15: =IFERROR(MEDIAN(C15:L15),0) -> 0.15779365
B17: Sales Expenses % Sales | C17: =IFERROR(HistoricalFS!C16,0) -> 0.077993626 | D17: =IFERROR(HistoricalFS!D16,0) -> 0.076966883 | E17: =IFERROR(HistoricalFS!E16,0) -> 0.075224753 | F17: =IFERROR(HistoricalFS!F16,0) -> 0.085382522 | G17: =IFERROR(HistoricalFS!G16,0) -> 0.069544338 | H17: =IFERROR(HistoricalFS!H16,0) -> 0.040737718 | I17: =IFERROR(HistoricalFS!I16,0) -> 0.043825684 | J17: =IFERROR(HistoricalFS!J16,0) -> 0.04603896 | ... L17: =IFERROR(HistoricalFS!L16,0) -> 0.043984294 | N17: =IFERROR(AVERAGE(C17:L17),0) -> 0.060665004 | O17: =IFERROR(MEDIAN(C17:L17),0) -> 0.058247799
B18: Depreciation % Sales | C18: =IFERROR(HistoricalFS!C25,0) -> 0.023366058 | D18: =IFERROR(HistoricalFS!D25,0) -> 0.024867122 | E18: =IFERROR(HistoricalFS!E25,0) -> 0.026417288 | F18: =IFERROR(HistoricalFS!F25,0) -> 0.024324161 | G18: =IFERROR(HistoricalFS!G25,0) -> 0.031864392 | H18: =IFERROR(HistoricalFS!H25,0) -> 0.032516522 | I18: =IFERROR(HistoricalFS!I25,0) -> 0.028575891 | J18: =IFERROR(HistoricalFS!J25,0) -> 0.028787125 | ... L18: =IFERROR(HistoricalFS!L25,0) -> 0.029523284 | N18: =IFERROR(AVERAGE(C18:L18),0) -> 0.02806837 | O18: =IFERROR(MEDIAN(C18:L18),0) -> 0.028681508
B19: Operating Income % Sales | C19: =C13 -> 0.25015615 | D19: =D13 -> 0.24678757 | E19: =E13 -> 0.24047815 | F19: =F13 -> 0.21964318 | G19: =G13 -> 0.2133912 | H19: =H13 -> 0.2450633 | I19: =I13 -> 0.23030886 | J19: =J13 -> 0.21057186 | ... L19: =L13 -> 0.21120314 | N19: =IFERROR(AVERAGE(C19:L19),0) -> 0.22741955 | O19: =IFERROR(MEDIAN(C19:L19),0) -> 0.22497602
B21: Return on Capital Employed | C21: =IFERROR((HistoricalFS!C18-HistoricalFS!C24)/SUM(HistoricalFS!C47:C49),0) -> 0.25298005 | D21: =IFERROR((HistoricalFS!D18-HistoricalFS!D24)/SUM(HistoricalFS!D47:D49),0) -> 0.24500594 | E21: =IFERROR((HistoricalFS!E18-HistoricalFS!E24)/SUM(HistoricalFS!E47:E49),0) -> 0.26121713 | F21: =IFERROR((HistoricalFS!F18-HistoricalFS!F24)/SUM(HistoricalFS!F47:F49),0) -> 0.27959291 | G21: =IFERROR((HistoricalFS!G18-HistoricalFS!G24)/SUM(HistoricalFS!G47:G49),0) -> 0.27644365 | H21: =IFERROR((HistoricalFS!H18-HistoricalFS!H24)/SUM(HistoricalFS!H47:H49),0) -> 0.30145943 | I21: =IFERROR((HistoricalFS!I18-HistoricalFS!I24)/SUM(HistoricalFS!I47:I49),0) -> 0.34661734 | J21: =IFERROR((HistoricalFS!J18-HistoricalFS!J24)/SUM(HistoricalFS!J47:J49),0) -> 0.3692089 | ... L21: =IFERROR((HistoricalFS!L18-HistoricalFS!L24)/SUM(HistoricalFS!L47:L49),0) -> 0.33085684 | N21: =IFERROR(AVERAGE(C21:L21),0) -> 0.29924519 | O21: =IFERROR(MEDIAN(C21:L21),0) -> 0.29052617
B22: Retained Earnings % | C22: =IFERROR(HistoricalFS!C44,0) -> 0.46490501 | D22: =IFERROR(HistoricalFS!D44,0) -> 0.47875785 | E22: =IFERROR(HistoricalFS!E44,0) -> 0.25573203 | F22: =IFERROR(HistoricalFS!F44,0) -> 0.26384898 | G22: =IFERROR(HistoricalFS!G44,0) -> 0.46321191 | H22: =IFERROR(HistoricalFS!H44,0) -> 0.33401463 | I22: =IFERROR(HistoricalFS!I44,0) -> 0.3447383 | J22: =IFERROR(HistoricalFS!J44,0) -> 0.34277573 | ... L22: =IFERROR(HistoricalFS!L44,0) -> 0.22990065 | N22: =IFERROR(AVERAGE(C22:L22),0) -> 0.32932122 | O22: =IFERROR(MEDIAN(C22:L22),0) -> 0.33839518
B23: Return on Equity % | C23: =IFERROR(HistoricalFS!C33/SUM(HistoricalFS!C47:C48),0) -> 0.16793535 | D23: =IFERROR(HistoricalFS!D33/SUM(HistoricalFS!D47:D48),0) -> 0.16385434 | E23: =IFERROR(HistoricalFS!E33/SUM(HistoricalFS!E47:E48),0) -> 0.1958936 | F23: =IFERROR(HistoricalFS!F33/SUM(HistoricalFS!F47:F48),0) -> 0.19289278 | G23: =IFERROR(HistoricalFS!G33/SUM(HistoricalFS!G47:G48),0) -> 0.21139801 | H23: =IFERROR(HistoricalFS!H33/SUM(HistoricalFS!H47:H48),0) -> 0.22556352 | I23: =IFERROR(HistoricalFS!I33/SUM(HistoricalFS!I47:I48),0) -> 0.26345056 | J23: =IFERROR(HistoricalFS!J33/SUM(HistoricalFS!J47:J48),0) -> 0.28388611 | ... L23: =IFERROR(HistoricalFS!L33/SUM(HistoricalFS!L47:L48),0) -> 0.24160387 | N23: =IFERROR(AVERAGE(C23:L23),0) -> 0.21908946 | O23: =IFERROR(MEDIAN(C23:L23),0) -> 0.21848076
B24: Self Sustained Growth Rate | C24: =IFERROR(C22*C23,0) -> 0.078073983 | D24: =IFERROR(D22*D23,0) -> 0.078446551 | E24: =IFERROR(E22*E23,0) -> 0.050096268 | F24: =IFERROR(F22*F23,0) -> 0.050894562 | G24: =IFERROR(G22*G23,0) -> 0.097922078 | H24: =IFERROR(H22*H23,0) -> 0.075341515 | I24: =IFERROR(I22*I23,0) -> 0.0908215 | J24: =IFERROR(J22*J23,0) -> 0.097309268 | ... L24: =IFERROR(L22*L23,0) -> 0.055544887 | N24: =IFERROR(AVERAGE(C24:L24),0) -> 0.070263846 | O24: =IFERROR(MEDIAN(C24:L24),0) -> 0.076707749
B25: Interest Coverage Ratio | C25: =IFERROR((HistoricalFS!C18-HistoricalFS!C24)/HistoricalFS!C21,0) -> 0 | D25: =IFERROR((HistoricalFS!D18-HistoricalFS!D24)/HistoricalFS!D21,0) -> 0 | E25: =IFERROR((HistoricalFS!E18-HistoricalFS!E24)/HistoricalFS!E21,0) -> 0 | F25: =IFERROR((HistoricalFS!F18-HistoricalFS!F24)/HistoricalFS!F21,0) -> 0 | G25: =IFERROR((HistoricalFS!G18-HistoricalFS!G24)/HistoricalFS!G21,0) -> 113.96471 | H25: =IFERROR((HistoricalFS!H18-HistoricalFS!H24)/HistoricalFS!H21,0) -> 126.26667 | I25: =IFERROR((HistoricalFS!I18-HistoricalFS!I24)/HistoricalFS!I21,0) -> 140.075 | J25: =IFERROR((HistoricalFS!J18-HistoricalFS!J24)/HistoricalFS!J21,0) -> 108.82042 | ... L25: =IFERROR((HistoricalFS!L18-HistoricalFS!L24)/HistoricalFS!L21,0) -> 82.75 | N25: =IFERROR(AVERAGE(C25:L25),0) -> 63.94236 | O25: =IFERROR(MEDIAN(C25:L25),0) -> 75.148404
B27: Debtor Turnover Ratio | C27: =IFERROR(HistoricalFS!C6/HistoricalFS!C59,0) -> 5.5111209 | D27: =IFERROR(HistoricalFS!D6/HistoricalFS!D59,0) -> 5.557864 | E27: =IFERROR(HistoricalFS!E6/HistoricalFS!E59,0) -> 5.3661543 | F27: =IFERROR(HistoricalFS!F6/HistoricalFS!F59,0) -> 5.5759763 | G27: =IFERROR(HistoricalFS!G6/HistoricalFS!G59,0) -> 4.9110726 | H27: =IFERROR(HistoricalFS!H6/HistoricalFS!H59,0) -> 5.207422 | I27: =IFERROR(HistoricalFS!I6/HistoricalFS!I59,0) -> 5.3591065 | J27: =IFERROR(HistoricalFS!J6/HistoricalFS!J59,0) -> 5.7727738 | ... L27: =IFERROR(HistoricalFS!L6/HistoricalFS!L59,0) -> 5.2310803 | N27: =IFERROR(AVERAGE(C27:L27),0) -> 5.3582161 | O27: =IFERROR(MEDIAN(C27:L27),0) -> 5.3626304
B28: Creditor Turnover Ratio | C28: =IFERROR(HistoricalFS!C6/HistoricalFS!C50,0) -> 4.6758275 | D28: =IFERROR(HistoricalFS!D6/HistoricalFS!D50,0) -> 4.8343922 | E28: =IFERROR(HistoricalFS!E6/HistoricalFS!E50,0) -> 4.8885346 | F28: =IFERROR(HistoricalFS!F6/HistoricalFS!F50,0) -> 4.3244586 | G28: =IFERROR(HistoricalFS!G6/HistoricalFS!G50,0) -> 4.1806419 | H28: =IFERROR(HistoricalFS!H6/HistoricalFS!H50,0) -> 3.8889878 | I28: =IFERROR(HistoricalFS!I6/HistoricalFS!I50,0) -> 3.3878568 | J28: =IFERROR(HistoricalFS!J6/HistoricalFS!J50,0) -> 3.5893128 | ... L28: =IFERROR(HistoricalFS!L6/HistoricalFS!L50,0) -> 3.7254857 | N28: =IFERROR(AVERAGE(C28:L28),0) -> 4.1254089 | O28: =IFERROR(MEDIAN(C28:L28),0) -> 4.0348149
B29: Inventory Turnover Ratio | C29: =IFERROR(HistoricalFS!C6/HistoricalFS!C60,0) -> 0 | D29: =IFERROR(HistoricalFS!D6/HistoricalFS!D60,0) -> 0 | E29: =IFERROR(HistoricalFS!E6/HistoricalFS!E60,0) -> 0 | F29: =IFERROR(HistoricalFS!F6/HistoricalFS!F60,0) -> 0 | G29: =IFERROR(HistoricalFS!G6/HistoricalFS!G60,0) -> 0 | H29: =IFERROR(HistoricalFS!H6/HistoricalFS!H60,0) -> 0 | I29: =IFERROR(HistoricalFS!I6/HistoricalFS!I60,0) -> 0 | J29: =IFERROR(HistoricalFS!J6/HistoricalFS!J60,0) -> 0 | ... L29: =IFERROR(HistoricalFS!L6/HistoricalFS!L60,0) -> 0 | N29: =IFERROR(AVERAGE(C29:L29),0) -> 0 | O29: =IFERROR(MEDIAN(C29:L29),0) -> 0
B30: Fixed Assets Turnover | C30: =IFERROR(HistoricalFS!C6/HistoricalFS!C53,0) -> 4.6646496 | D30: =IFERROR(HistoricalFS!D6/HistoricalFS!D53,0) -> 4.8299598 | E30: =IFERROR(HistoricalFS!E6/HistoricalFS!E53,0) -> 5.6085573 | F30: =IFERROR(HistoricalFS!F6/HistoricalFS!F53,0) -> 5.2625716 | G30: =IFERROR(HistoricalFS!G6/HistoricalFS!G53,0) -> 3.8165118 | H30: =IFERROR(HistoricalFS!H6/HistoricalFS!H53,0) -> 3.939306 | I30: =IFERROR(HistoricalFS!I6/HistoricalFS!I53,0) -> 4.7147674 | J30: =IFERROR(HistoricalFS!J6/HistoricalFS!J53,0) -> 5.0219675 | ... L30: =IFERROR(HistoricalFS!L6/HistoricalFS!L53,0) -> 5.2643648 | N30: =IFERROR(AVERAGE(C30:L30),0) -> 4.8685975 | O30: =IFERROR(MEDIAN(C30:L30),0) -> 4.9259636
B31: Capital Turnover Ratio | C31: =IFERROR(HistoricalFS!C6/SUM(HistoricalFS!C47:C48),0) -> 1.0112885 | D31: =IFERROR(HistoricalFS!D6/SUM(HistoricalFS!D47:D48),0) -> 0.99278073 | E31: =IFERROR(HistoricalFS!E6/SUM(HistoricalFS!E47:E48),0) -> 1.0862406 | F31: =IFERROR(HistoricalFS!F6/SUM(HistoricalFS!F47:F48),0) -> 1.2729414 | G31: =IFERROR(HistoricalFS!G6/SUM(HistoricalFS!G47:G48),0) -> 1.3871811 | H31: =IFERROR(HistoricalFS!H6/SUM(HistoricalFS!H47:H48),0) -> 1.3159225 | I31: =IFERROR(HistoricalFS!I6/SUM(HistoricalFS!I47:I48),0) -> 1.6143464 | J31: =IFERROR(HistoricalFS!J6/SUM(HistoricalFS!J47:J48),0) -> 1.9463312 | ... L31: =IFERROR(HistoricalFS!L6/SUM(HistoricalFS!L47:L48),0) -> 1.7010374 | N31: =IFERROR(AVERAGE(C31:L31),0) -> 1.4072021 | O31: =IFERROR(MEDIAN(C31:L31),0) -> 1.3515518
B33: (in days)
B34: Debtor Days | C34: =IFERROR(365/C27,0) -> 66.229721 | D34: =IFERROR(365/D27,0) -> 65.672712 | E34: =IFERROR(365/E27,0) -> 68.018916 | F34: =IFERROR(365/F27,0) -> 65.459389 | G34: =IFERROR(365/G27,0) -> 74.321849 | H34: =IFERROR(365/H27,0) -> 70.092265 | I34: =IFERROR(365/I27,0) -> 68.108368 | J34: =IFERROR(365/J27,0) -> 63.227837 | ... L34: =IFERROR(365/L27,0) -> 69.775262 | N34: =IFERROR(AVERAGE(C34:L34),0) -> 68.262133 | O34: =IFERROR(MEDIAN(C34:L34),0) -> 68.063642
B35: Payable Days | C35: =IFERROR(365/C28,0) -> 78.06105 | D35: =IFERROR(365/D28,0) -> 75.500701 | E35: =IFERROR(365/E28,0) -> 74.664502 | F35: =IFERROR(365/F28,0) -> 84.403629 | G35: =IFERROR(365/G28,0) -> 87.307167 | H35: =IFERROR(365/H28,0) -> 93.854756 | I35: =IFERROR(365/I28,0) -> 107.73773 | J35: =IFERROR(365/J28,0) -> 101.69078 | ... L35: =IFERROR(365/L28,0) -> 97.973802 | N35: =IFERROR(AVERAGE(C35:L35),0) -> 89.830496 | O35: =IFERROR(MEDIAN(C35:L35),0) -> 90.580961
B36: Inventory Days | C36: =IFERROR(365/C29,0) -> 0 | D36: =IFERROR(365/D29,0) -> 0 | E36: =IFERROR(365/E29,0) -> 0 | F36: =IFERROR(365/F29,0) -> 0 | G36: =IFERROR(365/G29,0) -> 0 | H36: =IFERROR(365/H29,0) -> 0 | I36: =IFERROR(365/I29,0) -> 0 | J36: =IFERROR(365/J29,0) -> 0 | ... L36: =IFERROR(365/L29,0) -> 0 | N36: =IFERROR(AVERAGE(C36:L36),0) -> 0 | O36: =IFERROR(MEDIAN(C36:L36),0) -> 0
B37: Cash Conversion Cycle | C37: =IFERROR((SUM(C34,C36)-C35),0) -> -11.831329 | D37: =IFERROR((SUM(D34,D36)-D35),0) -> -9.827989 | E37: =IFERROR((SUM(E34,E36)-E35),0) -> -6.6455858 | F37: =IFERROR((SUM(F34,F36)-F35),0) -> -18.944239 | G37: =IFERROR((SUM(G34,G36)-G35),0) -> -12.985318 | H37: =IFERROR((SUM(H34,H36)-H35),0) -> -23.762491 | I37: =IFERROR((SUM(I34,I36)-I35),0) -> -39.62936 | J37: =IFERROR((SUM(J34,J36)-J35),0) -> -38.462938 | ... L37: =IFERROR((SUM(L34,L36)-L35),0) -> -28.19854 | N37: =IFERROR(AVERAGE(C37:L37),0) -> -21.568364 | O37: =IFERROR(MEDIAN(C37:L37),0) -> -21.353365
B39: CFO/Sales | C39: =IFERROR(HistoricalFS!C77/HistoricalFS!C6,0) -> 0.12943419 | D39: =IFERROR(HistoricalFS!D77/HistoricalFS!D6,0) -> 0.13689329 | E39: =IFERROR(HistoricalFS!E77/HistoricalFS!E6,0) -> 0.18862199 | F39: =IFERROR(HistoricalFS!F77/HistoricalFS!F6,0) -> 0.17403084 | G39: =IFERROR(HistoricalFS!G77/HistoricalFS!G6,0) -> 0.16120541 | H39: =IFERROR(HistoricalFS!H77/HistoricalFS!H6,0) -> 0.2387929 | I39: =IFERROR(HistoricalFS!I77/HistoricalFS!I6,0) -> 0.18464991 | J39: =IFERROR(HistoricalFS!J77/HistoricalFS!J6,0) -> 0.1098544 | ... L39: =IFERROR(HistoricalFS!L77/HistoricalFS!L6,0) -> 0.2171851 | N39: =IFERROR(AVERAGE(C39:L39),0) -> 0.167165 | O39: =IFERROR(MEDIAN(C39:L39),0) -> 0.16761812
B40: CFO/Total Assets | C40: =IFERROR(HistoricalFS!C77/HistoricalFS!C64,0) -> 0.10761938 | D40: =IFERROR(HistoricalFS!D77/HistoricalFS!D64,0) -> 0.11275076 | E40: =IFERROR(HistoricalFS!E77/HistoricalFS!E64,0) -> 0.16763916 | F40: =IFERROR(HistoricalFS!F77/HistoricalFS!F64,0) -> 0.17115124 | G40: =IFERROR(HistoricalFS!G77/HistoricalFS!G64,0) -> 0.15943355 | H40: =IFERROR(HistoricalFS!H77/HistoricalFS!H64,0) -> 0.22315856 | I40: =IFERROR(HistoricalFS!I77/HistoricalFS!I64,0) -> 0.19242005 | J40: =IFERROR(HistoricalFS!J77/HistoricalFS!J64,0) -> 0.12940223 | ... L40: =IFERROR(HistoricalFS!L77/HistoricalFS!L64,0) -> 0.23951419 | N40: =IFERROR(AVERAGE(C40:L40),0) -> 0.16496238 | O40: =IFERROR(MEDIAN(C40:L40),0) -> 0.16353636
B41: CFO/Total Debt | C41: =IFERROR(HistoricalFS!C77/HistoricalFS!C49,0) -> 0 | D41: =IFERROR(HistoricalFS!D77/HistoricalFS!D49,0) -> 0 | E41: =IFERROR(HistoricalFS!E77/HistoricalFS!E49,0) -> 0 | F41: =IFERROR(HistoricalFS!F77/HistoricalFS!F49,0) -> 0 | G41: =IFERROR(HistoricalFS!G77/HistoricalFS!G49,0) -> 3.1590762 | H41: =IFERROR(HistoricalFS!H77/HistoricalFS!H49,0) -> 4.5055399 | I41: =IFERROR(HistoricalFS!I77/HistoricalFS!I49,0) -> 4.1032152 | J41: =IFERROR(HistoricalFS!J77/HistoricalFS!J49,0) -> 1.9427642 | ... L41: =IFERROR(HistoricalFS!L77/HistoricalFS!L49,0) -> 4.3027835 | N41: =IFERROR(AVERAGE(C41:L41),0) -> 2.0421323 | O41: =IFERROR(MEDIAN(C41:L41),0) -> 2.1753539

Sheet Forecasting
B2: ='Data Sheet'!B1&" - "&'Data Sheet'!A17&" Forecasting " -> INFOSYS LTD - Sales Forecasting | H2: ='Data Sheet'!B1&" - "&HistoricalFS!B18&" Forecasting " -> INFOSYS LTD - EBITDA Forecasting | N2: ='Data Sheet'!B1&" - "&HistoricalFS!B38&" Forecasting " -> INFOSYS LTD - EPS Forecasting
B3: Year Weight | C3: Year | D3: Sales | E3: Sales Growth | H3: Year Weight | I3: Year | J3: Sales | K3: Sales Growth | N3: Year Weight | O3: Year | P3: Sales | Q3: Sales Growth
B4: 1 | C4: ='Data Sheet'!B16 -> 42460 | D4: {=TRANSPOSE('Data Sheet'!B17:K17)} -> 62441 | H4: 1 | I4: =C4 -> 42460 | J4: {=TRANSPOSE(HistoricalFS!C18:L18)} -> 17079 | N4: 1 | O4: =I4 -> 42460 | P4: {=TRANSPOSE(HistoricalFS!C38:L38)} -> 22.571236
B5: =B4+1 -> 2 | C5: =C4+365 -> 42825 | D5: 68484 | E5: =D5/D4-1 -> 0.09677936 | H5: =H4+1 -> 2 | I5: =I4+365 -> 42825 | J5: 18604 | K5: =J5/J4-1 -> 0.089290942 | N5: =N4+1 -> 2 | O5: =O4+365 -> 42825 | P5: 24.604367 | Q5: =P5/P4-1 -> 0.090076189
B6: =B5+1 -> 3 | C6: =C5+365 -> 43190 | D6: 70522 | E6: =D6/D5-1 -> 0.029758776 | H6: =H5+1 -> 3 | I6: =I5+365 -> 43190 | J6: 18822 | K6: =J6/J5-1 -> 0.01171791 | N6: =N5+1 -> 3 | O6: =O5+365 -> 43190 | P6: 29.114967 | Q6: =P6/P5-1 -> 0.18332521
B7: =B6+1 -> 4 | C7: =C6+365 -> 43555 | D7: 82675 | E7: =D7/D6-1 -> 0.1723292 | H7: =H6+1 -> 4 | I7: =I6+365 -> 43555 | J7: 20170 | K7: =J7/J6-1 -> 0.071618319 | N7: =N6+1 -> 4 | O7: =O6+365 -> 43555 | P7: 28.67541 | Q7: =P7/P6-1 -> -0.015097286
B8: =B7+1 -> 5 | C8: =C7+365 -> 43920 | D8: 90791 | E8: =D8/D7-1 -> 0.098167523 | H8: =H7+1 -> 5 | I8: =I7+365 -> 43920 | J8: 22267 | K8: =J8/J7-1 -> 0.10396629 | N8: =N7+1 -> 5 | O8: =O7+365 -> 43920 | P8: 32.486499 | Q8: =P8/P7-1 -> 0.13290442
B9: =B8+1 -> 6 | C9: =C8+365 -> 44285 | D9: 100472 | E9: =D9/D8-1 -> 0.10662951 | H9: =H8+1 -> 6 | I9: =I8+365 -> 44285 | J9: 27889 | K9: =J9/J8-1 -> 0.25248125 | N9: =N8+1 -> 6 | O9: =O8+365 -> 44285 | P9: 40.420588 | Q9: =P9/P8-1 -> 0.24422727
B10: =B9+1 -> 7 | C10: =C9+365 -> 44650 | D10: 121641 | E10: =D10/D9-1 -> 0.21069552 | H10: =H9+1 -> 7 | I10: =I9+365 -> 44650 | J10: 31491 | K10: =J10/J9-1 -> 0.12915486 | N10: =N9+1 -> 7 | O10: =O9+365 -> 44650 | P10: 47.189008 | Q10: =P10/P9-1 -> 0.16744981
B11: =B10+1 -> 8 | C11: =C10+365 -> 45015 | D11: 146767 | E11: =D11/D10-1 -> 0.20655864 | H11: =H10+1 -> 8 | I11: =I10+365 -> 45015 | J11: 35130 | K11: =J11/J10-1 -> 0.11555683 | N11: =N10+1 -> 8 | O11: =O10+365 -> 45015 | P11: 51.60054 | Q11: =P11/P10-1 -> 0.093486431
B12: =B11+1 -> 9 | C12: =C11+365 -> 45380 | D12: 153670 | E12: =D12/D11-1 -> 0.047033734 | H12: =H11+1 -> 9 | I12: =I11+365 -> 45380 | J12: 36425 | K12: =J12/J11-1 -> 0.03686308 | N12: =N11+1 -> 9 | O12: =O11+365 -> 45380 | P12: 51.885133 | Q12: =P12/P11-1 -> 0.0055153183
B13: =B12+1 -> 10 | C13: =C12+365 -> 45745 | D13: 162990 | E13: =D13/D12-1 -> 0.060649444 | H13: =H12+1 -> 10 | I13: =I12+365 -> 45745 | J13: 39236 | K13: =J13/J12-1 -> 0.077172272 | N13: =N12+1 -> 10 | O13: =O12+365 -> 45745 | P13: 55.73881 | Q13: =P13/P12-1 -> 0.074273236
B14: =B13+1 -> 11 | C14: =C13+365 -> 46110 | D14: =FORECAST(B14,$D$4:$D$13,$B$4:$B$13) -> 173013.53 | E14: =D14/D13-1 -> 0.061497842 | H14: =H13+1 -> 11 | I14: =I13+365 -> 46110 | J14: =FORECAST(H14,$J$4:$J$13,$H$4:$H$13) -> 41554.133 | K14: =J14/J13-1 -> 0.059081796 | N14: =N13+1 -> 11 | O14: =O13+365 -> 46110 | P14: =FORECAST(N14,$P$4:$P$13,$N$4:$N$13) -> 60.607865 | Q14: =P14/P13-1 -> 0.087354846
B15: =B14+1 -> 12 | C15: =C14+365 -> 46475 | D15: =FORECAST(B15,$D$4:$D$13,$B$4:$B$13) -> 185189.58 | E15: =D15/D14-1 -> 0.070376243 | H15: =H14+1 -> 12 | I15: =I14+365 -> 46475 | J15: =FORECAST(H15,$J$4:$J$13,$H$4:$H$13) -> 44252.83 | K15: =J15/J14-1 -> 0.064944128 | N15: =N14+1 -> 12 | O15: =O14+365 -> 46475 | P15: =FORECAST(N15,$P$4:$P$13,$N$4:$N$13) -> 64.640449 | Q15: =P15/P14-1 -> 0.066535647
B16: =B15+1 -> 13 | C16: =C15+365 -> 46840 | D16: =FORECAST(B16,$D$4:$D$13,$B$4:$B$13) -> 197365.62 | E16: =D16/D15-1 -> 0.06574907 | H16: =H15+1 -> 13 | I16: =I15+365 -> 46840 | J16: =FORECAST(H16,$J$4:$J$13,$H$4:$H$13) -> 46951.527 | K16: =J16/J15-1 -> 0.060983602 | N16: =N15+1 -> 13 | O16: =O15+365 -> 46840 | P16: =FORECAST(N16,$P$4:$P$13,$N$4:$N$13) -> 68.673032 | Q16: =P16/P15-1 -> 0.062384832
B17: =B16+1 -> 14 | C17: =C16+365 -> 47205 | D17: =FORECAST(B17,$D$4:$D$13,$B$4:$B$13) -> 209541.66 | E17: =D17/D16-1 -> 0.061692824 | H17: =H16+1 -> 14 | I17: =I16+365 -> 47205 | J17: =FORECAST(H17,$J$4:$J$13,$H$4:$H$13) -> 49650.224 | K17: =J17/J16-1 -> 0.057478364 | N17: =N16+1 -> 14 | O17: =O16+365 -> 47205 | P17: =FORECAST(N17,$P$4:$P$13,$N$4:$N$13) -> 72.705616 | Q17: =P17/P16-1 -> 0.058721501
B18: =B17+1 -> 15 | C18: =C17+365 -> 47570 | D18: =FORECAST(B18,$D$4:$D$13,$B$4:$B$13) -> 221717.7 | E18: =D18/D17-1 -> 0.058107979 | H18: =H17+1 -> 15 | I18: =I17+365 -> 47570 | J18: =FORECAST(H18,$J$4:$J$13,$H$4:$H$13) -> 52348.921 | K18: =J18/J17-1 -> 0.054354175 | N18: =N17+1 -> 15 | O18: =O17+365 -> 47570 | P18: =FORECAST(N18,$P$4:$P$13,$N$4:$N$13) -> 76.738199 | Q18: =P18/P17-1 -> 0.05546454
B22: Done by linear forecasting
B27: (Why we should not take these)
B28: Arthematic Growth | D28: =AVERAGE(E5:E13) -> 0.11428908
B29: Geometric Growth | D29: =_xlfn.RRI(B13,D4,D13) -> 0.10070037
B31: Standard Deviation | D31: =_xlfn.STDEV.S(E5:E13) -> 0.067405079

Sheet Common Size Statement
A2: # | B2: ="Common Size Income Statement"&" "&"- "&'Data Sheet'!$B$1 -> Common Size Income Statement - INFOSYS LTD
B4: Particulars | C4: ='Data Sheet'!B16 -> 42460 | D4: ='Data Sheet'!C16 -> 42825 | E4: ='Data Sheet'!D16 -> 43190 | F4: ='Data Sheet'!E16 -> 43555 | G4: ='Data Sheet'!F16 -> 43921 | H4: ='Data Sheet'!G16 -> 44286 | I4: ='Data Sheet'!H16 -> 44651 | J4: ='Data Sheet'!I16 -> 45016 | ... L4: ='Data Sheet'!K16 -> 45747
B6: ='Data Sheet'!A17 -> Sales | C6: ='Data Sheet'!B17/'Data Sheet'!B$17 -> 1 | D6: ='Data Sheet'!C17/'Data Sheet'!C$17 -> 1 | E6: ='Data Sheet'!D17/'Data Sheet'!D$17 -> 1 | F6: ='Data Sheet'!E17/'Data Sheet'!E$17 -> 1 | G6: ='Data Sheet'!F17/'Data Sheet'!F$17 -> 1 | H6: ='Data Sheet'!G17/'Data Sheet'!G$17 -> 1 | I6: ='Data Sheet'!H17/'Data Sheet'!H$17 -> 1 | J6: ='Data Sheet'!I17/'Data Sheet'!I$17 -> 1 | ... L6: ='Data Sheet'!K17/'Data Sheet'!K$17 -> 1
B7: ='Data Sheet'!A18 -> Raw Material Cost | C7: ='Data Sheet'!B18/'Data Sheet'!B$17 -> 0 | D7: ='Data Sheet'!C18/'Data Sheet'!C$17 -> 0 | E7: ='Data Sheet'!D18/'Data Sheet'!D$17 -> 0 | F7: ='Data Sheet'!E18/'Data Sheet'!E$17 -> 0 | G7: ='Data Sheet'!F18/'Data Sheet'!F$17 -> 0 | H7: ='Data Sheet'!G18/'Data Sheet'!G$17 -> 0 | I7: ='Data Sheet'!H18/'Data Sheet'!H$17 -> 0 | J7: ='Data Sheet'!I18/'Data Sheet'!I$17 -> 0 | ... L7: ='Data Sheet'!K18/'Data Sheet'!K$17 -> 0
B8: ='Data Sheet'!A19 -> Change in Inventory | C8: ='Data Sheet'!B19/'Data Sheet'!B$17 -> 0 | D8: ='Data Sheet'!C19/'Data Sheet'!C$17 -> 0 | E8: ='Data Sheet'!D19/'Data Sheet'!D$17 -> 0 | F8: ='Data Sheet'!E19/'Data Sheet'!E$17 -> 0 | G8: ='Data Sheet'!F19/'Data Sheet'!F$17 -> 0 | H8: ='Data Sheet'!G19/'Data Sheet'!G$17 -> 0 | I8: ='Data Sheet'!H19/'Data Sheet'!H$17 -> 0 | J8: ='Data Sheet'!I19/'Data Sheet'!I$17 -> 0 | ... L8: ='Data Sheet'!K19/'Data Sheet'!K$17 -> 0
B9: ='Data Sheet'!A20 -> Power and Fuel | C9: ='Data Sheet'!B20/'Data Sheet'!B$17 -> 0.0034752807 | D9: ='Data Sheet'!C20/'Data Sheet'!C$17 -> 0.0033292448 | E9: ='Data Sheet'!D20/'Data Sheet'!D$17 -> 0.0029352542 | F9: ='Data Sheet'!E20/'Data Sheet'!E$17 -> 0.0026731176 | G9: ='Data Sheet'!F20/'Data Sheet'!F$17 -> 0.0025222764 | H9: ='Data Sheet'!G20/'Data Sheet'!G$17 -> 0.0014232821 | I9: ='Data Sheet'!H20/'Data Sheet'!H$17 -> 0.0010851604 | J9: ='Data Sheet'!I20/'Data Sheet'!I$17 -> 0.0011991797 | ... L9: ='Data Sheet'!K20/'Data Sheet'!K$17 -> 0.0013620468
B10: ='Data Sheet'!A21 -> Other Mfr. Exp | C10: ='Data Sheet'!B21/'Data Sheet'!B$17 -> 0.093848593 | D10: ='Data Sheet'!C21/'Data Sheet'!C$17 -> 0.098008294 | E10: ='Data Sheet'!D21/'Data Sheet'!D$17 -> 0.10331528 | F10: ='Data Sheet'!E21/'Data Sheet'!E$17 -> 0.11977018 | G10: ='Data Sheet'!F21/'Data Sheet'!F$17 -> 0.12210461 | H10: ='Data Sheet'!G21/'Data Sheet'!G$17 -> 0.12739868 | I10: ='Data Sheet'!H21/'Data Sheet'!H$17 -> 0.17009068 | J10: ='Data Sheet'!I21/'Data Sheet'!I$17 -> 0.1794 | ... L10: ='Data Sheet'!K21/'Data Sheet'!K$17 -> 0.18648383
B11: ='Data Sheet'!A22 -> Employee Cost | C11: ='Data Sheet'!B22/'Data Sheet'!B$17 -> 0.5511603 | D11: ='Data Sheet'!C22/'Data Sheet'!C$17 -> 0.55004089 | E11: ='Data Sheet'!D22/'Data Sheet'!D$17 -> 0.55162928 | F11: ='Data Sheet'!E22/'Data Sheet'!E$17 -> 0.54820683 | G11: ='Data Sheet'!F22/'Data Sheet'!F$17 -> 0.56057318 | H11: ='Data Sheet'!G22/'Data Sheet'!G$17 -> 0.5528605 | I11: ='Data Sheet'!H22/'Data Sheet'!H$17 -> 0.52611373 | J11: ='Data Sheet'!I22/'Data Sheet'!I$17 -> 0.53400288 | ... L11: ='Data Sheet'!K22/'Data Sheet'!K$17 -> 0.5274434
B12: ='Data Sheet'!A23 -> Selling and admin | C12: ='Data Sheet'!B23/'Data Sheet'!B$17 -> 0.07112314 | D12: ='Data Sheet'!C23/'Data Sheet'!C$17 -> 0.066935343 | E12: ='Data Sheet'!D23/'Data Sheet'!D$17 -> 0.065015173 | F12: ='Data Sheet'!E23/'Data Sheet'!E$17 -> 0.067166616 | G12: ='Data Sheet'!F23/'Data Sheet'!F$17 -> 0.059201903 | H12: ='Data Sheet'!G23/'Data Sheet'!G$17 -> 0.031789951 | I12: ='Data Sheet'!H23/'Data Sheet'!H$17 -> 0.035391028 | J12: ='Data Sheet'!I23/'Data Sheet'!I$17 -> 0.03611166 | ... L12: ='Data Sheet'!K23/'Data Sheet'!K$17 -> 0.037051353
B13: ='Data Sheet'!A24 -> Other Expenses | C13: ='Data Sheet'!B24/'Data Sheet'!B$17 -> 0.0068704857 | D13: ='Data Sheet'!C24/'Data Sheet'!C$17 -> 0.01003154 | E13: ='Data Sheet'!D24/'Data Sheet'!D$17 -> 0.01020958 | F13: ='Data Sheet'!E24/'Data Sheet'!E$17 -> 0.018215906 | G13: ='Data Sheet'!F24/'Data Sheet'!F$17 -> 0.010342435 | H13: ='Data Sheet'!G24/'Data Sheet'!G$17 -> 0.0089477665 | I13: ='Data Sheet'!H24/'Data Sheet'!H$17 -> 0.0084346561 | J13: ='Data Sheet'!I24/'Data Sheet'!I$17 -> 0.0099272997 | ... L13: ='Data Sheet'!K24/'Data Sheet'!K$17 -> 0.0069329407
B14: ='Data Sheet'!A25 -> Other Income | C14: ='Data Sheet'!B25/'Data Sheet'!B$17 -> 0.049967169 | D14: ='Data Sheet'!C25/'Data Sheet'!C$17 -> 0.04453595 | E14: ='Data Sheet'!D25/'Data Sheet'!D$17 -> 0.046949888 | F14: ='Data Sheet'!E25/'Data Sheet'!E$17 -> 0.034859389 | G14: ='Data Sheet'!F25/'Data Sheet'!F$17 -> 0.030873104 | H14: ='Data Sheet'!G25/'Data Sheet'!G$17 -> 0.021906601 | I14: ='Data Sheet'!H25/'Data Sheet'!H$17 -> 0.018866994 | J14: ='Data Sheet'!I25/'Data Sheet'!I$17 -> 0.01840332 | ... L14: ='Data Sheet'!K25/'Data Sheet'!K$17 -> 0.022087245
B15: ='Data Sheet'!A26 -> Depreciation | C15: ='Data Sheet'!B26/'Data Sheet'!B$17 -> 0.023366058 | D15: ='Data Sheet'!C26/'Data Sheet'!C$17 -> 0.024867122 | E15: ='Data Sheet'!D26/'Data Sheet'!D$17 -> 0.026417288 | F15: ='Data Sheet'!E26/'Data Sheet'!E$17 -> 0.024324161 | G15: ='Data Sheet'!F26/'Data Sheet'!F$17 -> 0.031864392 | H15: ='Data Sheet'!G26/'Data Sheet'!G$17 -> 0.032516522 | I15: ='Data Sheet'!H26/'Data Sheet'!H$17 -> 0.028575891 | J15: ='Data Sheet'!I26/'Data Sheet'!I$17 -> 0.028787125 | ... L15: ='Data Sheet'!K26/'Data Sheet'!K$17 -> 0.029523284
B16: ='Data Sheet'!A27 -> Interest | C16: ='Data Sheet'!B27/'Data Sheet'!B$17 -> 0 | D16: ='Data Sheet'!C27/'Data Sheet'!C$17 -> 0 | E16: ='Data Sheet'!D27/'Data Sheet'!D$17 -> 0 | F16: ='Data Sheet'!E27/'Data Sheet'!E$17 -> 0 | G16: ='Data Sheet'!F27/'Data Sheet'!F$17 -> 0.0018724323 | H16: ='Data Sheet'!G27/'Data Sheet'!G$17 -> 0.0019408392 | I16: ='Data Sheet'!H27/'Data Sheet'!H$17 -> 0.0016441825 | J16: ='Data Sheet'!I27/'Data Sheet'!I$17 -> 0.0019350399 | ... L16: ='Data Sheet'!K27/'Data Sheet'!K$17 -> 0.0025523038
B17: ='Data Sheet'!A28 -> Profit before tax | C17: ='Data Sheet'!B28/'Data Sheet'!B$17 -> 0.30012332 | D17: ='Data Sheet'!C28/'Data Sheet'!C$17 -> 0.29132352 | E17: ='Data Sheet'!D28/'Data Sheet'!D$17 -> 0.28742804 | F17: ='Data Sheet'!E28/'Data Sheet'!E$17 -> 0.25450257 | G17: ='Data Sheet'!F28/'Data Sheet'!F$17 -> 0.24239187 | H17: ='Data Sheet'!G28/'Data Sheet'!G$17 -> 0.26502906 | I17: ='Data Sheet'!H28/'Data Sheet'!H$17 -> 0.24753167 | J17: ='Data Sheet'!I28/'Data Sheet'!I$17 -> 0.22704014 | ... L17: ='Data Sheet'!K28/'Data Sheet'!K$17 -> 0.23073808
... B20: ='Data Sheet'!A31 -> Dividend Amount | C20: ='Data Sheet'!B31/'Data Sheet'!B$17 -> 0.088858282 | D20: ='Data Sheet'!C31/'Data Sheet'!C$17 -> 0.086028853 | E20: ='Data Sheet'!D31/'Data Sheet'!D$17 -> 0.13422194 | F20: ='Data Sheet'!E31/'Data Sheet'!E$17 -> 0.11155125 | G20: ='Data Sheet'!F31/'Data Sheet'!F$17 -> 0.081803262 | H20: ='Data Sheet'!G31/'Data Sheet'!G$17 -> 0.11415718 | I20: ='Data Sheet'!H31/'Data Sheet'!H$17 -> 0.10693434 | J20: ='Data Sheet'!I31/'Data Sheet'!I$17 -> 0.095860786 | ... L20: ='Data Sheet'!K31/'Data Sheet'!K$17 -> 0.10937972
B21: ='Data Sheet'!A33 -> EBITDA | C21: ='Data Sheet'!B33/'Data Sheet'!B$17 -> 0.32348937 | D21: ='Data Sheet'!C33/'Data Sheet'!C$17 -> 0.31619064 | E21: ='Data Sheet'!D33/'Data Sheet'!D$17 -> 0.31384532 | F21: ='Data Sheet'!E33/'Data Sheet'!E$17 -> 0.27875416 | G21: ='Data Sheet'!F33/'Data Sheet'!F$17 -> 0.27563305 | H21: ='Data Sheet'!G33/'Data Sheet'!G$17 -> 0.29876981 | I21: ='Data Sheet'!H33/'Data Sheet'!H$17 -> 0.27745579 | J21: ='Data Sheet'!I33/'Data Sheet'!I$17 -> 0.25767373 | ... L21: ='Data Sheet'!K33/'Data Sheet'!K$17 -> 0.26258666
A23: # | B23: ="Common Size Balance Sheet"&" "&"- "&'Data Sheet'!$B$1 -> Common Size Balance Sheet - INFOSYS LTD
B25: Particulars | C25: ='Data Sheet'!B56 -> 42460 | D25: ='Data Sheet'!C56 -> 42825 | E25: ='Data Sheet'!D56 -> 43190 | F25: ='Data Sheet'!E56 -> 43555 | G25: ='Data Sheet'!F56 -> 43921 | H25: ='Data Sheet'!G56 -> 44286 | I25: ='Data Sheet'!H56 -> 44651 | J25: ='Data Sheet'!I56 -> 45016 | ... L25: ='Data Sheet'!K56 -> 45747
B27: Total Liabilities | C27: ='Data Sheet'!B61/'Data Sheet'!B$61 -> 1 | D27: ='Data Sheet'!C61/'Data Sheet'!C$61 -> 1 | E27: ='Data Sheet'!D61/'Data Sheet'!D$61 -> 1 | F27: ='Data Sheet'!E61/'Data Sheet'!E$61 -> 1 | G27: ='Data Sheet'!F61/'Data Sheet'!F$61 -> 1 | H27: ='Data Sheet'!G61/'Data Sheet'!G$61 -> 1 | I27: ='Data Sheet'!H61/'Data Sheet'!H$61 -> 1 | J27: ='Data Sheet'!I61/'Data Sheet'!I$61 -> 1 | ... L27: ='Data Sheet'!K61/'Data Sheet'!K$61 -> 1
B28: ='Data Sheet'!A57 -> Equity Share Capital | C28: ='Data Sheet'!B57/'Data Sheet'!B$61 -> 0.015233428 | D28: ='Data Sheet'!C57/'Data Sheet'!C$61 -> 0.013758599 | E28: ='Data Sheet'!D57/'Data Sheet'!D$61 -> 0.013711578 | F28: ='Data Sheet'!E57/'Data Sheet'!E$61 -> 0.025813052 | G28: ='Data Sheet'!F57/'Data Sheet'!F$61 -> 0.023115468 | H28: ='Data Sheet'!G57/'Data Sheet'!G$61 -> 0.019756118 | I28: ='Data Sheet'!H57/'Data Sheet'!H$61 -> 0.017973254 | J28: ='Data Sheet'!I57/'Data Sheet'!I$61 -> 0.01660567 | ... L28: ='Data Sheet'!K57/'Data Sheet'!K$61 -> 0.014026185
B29: ='Data Sheet'!A58 -> Reserves | C29: ='Data Sheet'!B58/'Data Sheet'!B$61 -> 0.80694559 | D29: ='Data Sheet'!C58/'Data Sheet'!C$61 -> 0.8158705 | E29: ='Data Sheet'!D58/'Data Sheet'!D$61 -> 0.80448399 | F29: ='Data Sheet'!E58/'Data Sheet'!E$61 -> 0.74677039 | G29: ='Data Sheet'!F58/'Data Sheet'!F$61 -> 0.68984749 | H29: ='Data Sheet'!G58/'Data Sheet'!G$61 -> 0.69041307 | I29: ='Data Sheet'!H58/'Data Sheet'!H$61 -> 0.627539 | J29: ='Data Sheet'!I58/'Data Sheet'!I$61 -> 0.58860638 | ... L29: ='Data Sheet'!K58/'Data Sheet'!K$61 -> 0.63429074
B30: ='Data Sheet'!A59 -> Borrowings | C30: ='Data Sheet'!B59/'Data Sheet'!B$61 -> 0 | D30: ='Data Sheet'!C59/'Data Sheet'!C$61 -> 0 | E30: ='Data Sheet'!D59/'Data Sheet'!D$61 -> 0 | F30: ='Data Sheet'!E59/'Data Sheet'!E$61 -> 0 | G30: ='Data Sheet'!F59/'Data Sheet'!F$61 -> 0.05046841 | H30: ='Data Sheet'!G59/'Data Sheet'!G$61 -> 0.049529816 | I30: ='Data Sheet'!H59/'Data Sheet'!H$61 -> 0.046894945 | J30: ='Data Sheet'!I59/'Data Sheet'!I$61 -> 0.066607275 | ... L30: ='Data Sheet'!K59/'Data Sheet'!K$61 -> 0.055664941
B31: ='Data Sheet'!A60 -> Other Liabilities | C31: ='Data Sheet'!B60/'Data Sheet'!B$61 -> 0.17782098 | D31: ='Data Sheet'!C60/'Data Sheet'!C$61 -> 0.1703709 | E31: ='Data Sheet'!D60/'Data Sheet'!D$61 -> 0.18180443 | F31: ='Data Sheet'!E60/'Data Sheet'!E$61 -> 0.22741655 | G31: ='Data Sheet'!F60/'Data Sheet'!F$61 -> 0.23656863 | H31: ='Data Sheet'!G60/'Data Sheet'!G$61 -> 0.24030099 | I31: ='Data Sheet'!H60/'Data Sheet'!H$61 -> 0.3075928 | J31: ='Data Sheet'!I60/'Data Sheet'!I$61 -> 0.32818068 | ... L31: ='Data Sheet'!K60/'Data Sheet'!K$61 -> 0.29601813
B33: Total Assets | C33: ='Data Sheet'!B76/'Data Sheet'!B$76 -> 1 | D33: ='Data Sheet'!C76/'Data Sheet'!C$76 -> 1 | E33: ='Data Sheet'!D76/'Data Sheet'!D$76 -> 1 | F33: ='Data Sheet'!E76/'Data Sheet'!E$76 -> 1 | G33: ='Data Sheet'!F76/'Data Sheet'!F$76 -> 1 | H33: ='Data Sheet'!G76/'Data Sheet'!G$76 -> 1 | I33: ='Data Sheet'!H76/'Data Sheet'!H$76 -> 1 | J33: ='Data Sheet'!I76/'Data Sheet'!I$76 -> 1 | ... L33: ='Data Sheet'!K76/'Data Sheet'!K$76 -> 1
B34: ='Data Sheet'!A62 -> Net Block | C34: ='Data Sheet'!B62/'Data Sheet'!B$76 -> 0.17824709 | D34: ='Data Sheet'!C62/'Data Sheet'!C$76 -> 0.17052725 | E34: ='Data Sheet'!D62/'Data Sheet'!D$76 -> 0.1584645 | F34: ='Data Sheet'!E62/'Data Sheet'!E$76 -> 0.18687698 | G34: ='Data Sheet'!F62/'Data Sheet'!F$76 -> 0.25913943 | H34: ='Data Sheet'!G62/'Data Sheet'!G$76 -> 0.23723154 | I34: ='Data Sheet'!H62/'Data Sheet'!H$76 -> 0.22102477 | J34: ='Data Sheet'!I62/'Data Sheet'!I$76 -> 0.23455809 | ... L34: ='Data Sheet'!K62/'Data Sheet'!K$76 -> 0.20948611
B35: ='Data Sheet'!A63 -> Capital Work in Progress | C35: ='Data Sheet'!B63/'Data Sheet'!B$76 -> 0.012783296 | D35: ='Data Sheet'!C63/'Data Sheet'!C$76 -> 0.01641651 | E35: ='Data Sheet'!D63/'Data Sheet'!D$76 -> 0.020239701 | F35: ='Data Sheet'!E63/'Data Sheet'!E$76 -> 0.016510837 | G35: ='Data Sheet'!F63/'Data Sheet'!F$76 -> 0.010392157 | H35: ='Data Sheet'!G63/'Data Sheet'!G$76 -> 0.0085758667 | I35: ='Data Sheet'!H63/'Data Sheet'!H$76 -> 0.0035638102 | J35: ='Data Sheet'!I63/'Data Sheet'!I$76 -> 0.0023114707 | ... L35: ='Data Sheet'!K63/'Data Sheet'!K$76 -> 0.0055076288
B36: ='Data Sheet'!A64 -> Investments | C36: ='Data Sheet'!B64/'Data Sheet'!B$76 -> 0.025193747 | D36: ='Data Sheet'!C64/'Data Sheet'!C$76 -> 0.19751527 | E36: ='Data Sheet'!D64/'Data Sheet'!D$76 -> 0.15328486 | F36: ='Data Sheet'!E64/'Data Sheet'!E$76 -> 0.13395427 | G36: ='Data Sheet'!F64/'Data Sheet'!F$76 -> 0.09577342 | H36: ='Data Sheet'!G64/'Data Sheet'!G$76 -> 0.13212602 | I36: ='Data Sheet'!H64/'Data Sheet'!H$76 -> 0.17411269 | J36: ='Data Sheet'!I64/'Data Sheet'!I$76 -> 0.15632926 | ... L36: ='Data Sheet'!K64/'Data Sheet'!K$76 -> 0.15928144
B37: ='Data Sheet'!A65 -> Other Assets | C37: ='Data Sheet'!B74/'Data Sheet'!B$76 -> 0.19751525 | D37: ='Data Sheet'!C74/'Data Sheet'!C$76 -> 0.19524222 | E37: ='Data Sheet'!D74/'Data Sheet'!D$76 -> 0.25263078 | F37: ='Data Sheet'!E74/'Data Sheet'!E$76 -> 0.2535151 | G37: ='Data Sheet'!F74/'Data Sheet'!F$76 -> 0.2301634 | H37: ='Data Sheet'!G74/'Data Sheet'!G$76 -> 0.21273172 | I37: ='Data Sheet'!H74/'Data Sheet'!H$76 -> 0.25716831 | J37: ='Data Sheet'!I74/'Data Sheet'!I$76 -> 0.30504992 | ... L37: ='Data Sheet'!K74/'Data Sheet'!K$76 -> 0.2494401
B38: ='Data Sheet'!A67 -> Receivables | C38: ='Data Sheet'!B67/'Data Sheet'!B$76 -> 0.15086953 | D38: ='Data Sheet'!C67/'Data Sheet'!C$76 -> 0.14819358 | E38: ='Data Sheet'!D67/'Data Sheet'!D$76 -> 0.16562276 | F38: ='Data Sheet'!E67/'Data Sheet'!E$76 -> 0.17637333 | G38: ='Data Sheet'!F67/'Data Sheet'!F$76 -> 0.20138344 | H38: ='Data Sheet'!G67/'Data Sheet'!G$76 -> 0.17946071 | I38: ='Data Sheet'!H67/'Data Sheet'!H$76 -> 0.19445039 | J38: ='Data Sheet'!I67/'Data Sheet'!I$76 -> 0.20405149 | ... L38: ='Data Sheet'!K67/'Data Sheet'!K$76 -> 0.21081904
B39: ='Data Sheet'!A68 -> Inventory | C39: ='Data Sheet'!B68/'Data Sheet'!B$76 -> 0 | D39: ='Data Sheet'!C68/'Data Sheet'!C$76 -> 0 | E39: ='Data Sheet'!D68/'Data Sheet'!D$76 -> 0 | F39: ='Data Sheet'!E68/'Data Sheet'!E$76 -> 0 | G39: ='Data Sheet'!F68/'Data Sheet'!F$76 -> 0 | H39: ='Data Sheet'!G68/'Data Sheet'!G$76 -> 0 | I39: ='Data Sheet'!H68/'Data Sheet'!H$76 -> 0 | J39: ='Data Sheet'!I68/'Data Sheet'!I$76 -> 0 | ... L39: ='Data Sheet'!K68/'Data Sheet'!K$76 -> 0
B40: ='Data Sheet'!A69 -> Cash & Bank | C40: ='Data Sheet'!B69/'Data Sheet'!B$76 -> 0.43539109 | D40: ='Data Sheet'!C69/'Data Sheet'!C$76 -> 0.27210516 | E40: ='Data Sheet'!D69/'Data Sheet'!D$76 -> 0.2497574 | F40: ='Data Sheet'!E69/'Data Sheet'!E$76 -> 0.23276949 | G40: ='Data Sheet'!F69/'Data Sheet'!F$76 -> 0.20314815 | H40: ='Data Sheet'!G69/'Data Sheet'!G$76 -> 0.22987415 | I40: ='Data Sheet'!H69/'Data Sheet'!H$76 -> 0.14968003 | J40: ='Data Sheet'!I69/'Data Sheet'!I$76 -> 0.097699766 | ... L40: ='Data Sheet'!K69/'Data Sheet'!K$76 -> 0.16546568

Sheet DCF>

Sheet WACC
B2: Weighted Average Cost of Capital
B4: All figures are in INR unless stated otherwise.
B6: Peer Companies
H7: Debt / | I7: Debt / | J7: Levered | K7: Unlevered
B8: Name of Companies | D8: Countary | E8: Total Debts | F8: Total Equity | G8: Tax Rate 1 | H8: Equity | I8: Capital | J8: Beta 2 | K8: Beta 3
B10: TCS | D10: India | E10: ='Beta Comps'!F3 -> 10932 | F10: ='Beta Comps'!E3 -> 1066286.6 | G10: 0.3 | H10: =E10/F10 -> 0.010252403 | I10: =E10/(F10+E10) -> 0.010148358 | J10: ='Bata - Regression'!AA18 -> -0.7250798 | K10: =J10/(1+(1-G10)*H10) -> -0.71991321
B11: Infosys | D11: India | E11: ='Beta Comps'!F4 -> 8796 | F11: ='Beta Comps'!E4 -> 607005.1 | G11: 0.3 | H11: =E11/F11 -> 0.014490817 | I11: =E11/(F11+E11) -> 0.014283833 | J11: ='Bata - Regression'!J18 -> -0.55864319 | K11: =J11/(1+(1-G11)*H11) -> -0.55303345
B12: HCL Technologies | D12: India | E12: ='Beta Comps'!F5 -> 6780 | F12: ='Beta Comps'!E5 -> 434403.52 | G12: 0.3 | H12: =E12/F12 -> 0.015607608 | I12: =E12/(F12+E12) -> 0.015367754 | J12: ='Bata - Regression'!AR18 -> -0.69639833 | K12: =J12/(1+(1-G12)*H12) -> -0.68887218
B13: Wipro | D13: India | E13: ='Beta Comps'!F6 -> 16163.7 | F13: ='Beta Comps'!E6 -> 241313.87 | G13: 0.3 | H13: =E13/F13 -> 0.06698206 | I13: =E13/(F13+E13) -> 0.062777119 | J13: ='Bata - Regression'!BI18 -> -0.36690988 | K13: =J13/(1+(1-G13)*H13) -> -0.35047691
B14: LTIMindtree | D14: India | E14: ='Beta Comps'!F7 -> 2382.6 | F14: ='Beta Comps'!E7 -> 166799.73 | G14: 0.3 | H14: =E14/F14 -> 0.014284196 | I14: =E14/(F14+E14) -> 0.014083031 | J14: ='Bata - Regression'!BZ18 -> -0.42203534 | K14: =J14/(1+(1-G14)*H14) -> -0.41785721
F16: Average | G16: =AVERAGE(G10:G14) -> 0.3 | H16: =AVERAGE(H10:H14) -> 0.024323417 | I16: =AVERAGE(I10:I14) -> 0.023332019 | J16: =AVERAGE(J10:J14) -> -0.55381331 | K16: =AVERAGE(K10:K14) -> -0.54603059
F17: Median | G17: =MEDIAN(G10:G14) -> 0.3 | H17: =MEDIAN(H10:H14) -> 0.014490817 | I17: =MEDIAN(I10:I14) -> 0.014283833 | J17: =MEDIAN(J10:J14) -> -0.55864319 | K17: =MEDIAN(K10:K14) -> -0.55303345
B20: Cost of Debt | G20: Cost of Equity
B22: Pre-Tax Cost of Debt | E22: =416/E11 -> 0.047294225 | G22: Risk Free Rate | K22: 0.07391
B23: Tax Rate | E23: =G17 -> 0.3 | G23: Equity Risk Premium | K23: =Rm!G7-WACC!K22 -> 0.077582308
B24: Post-Tax Cost of Debt | E24: =E22*(1-E23) -> 0.033105957 | G24: Levered Beta 4 | K24: =K33 -> -0.5622816
G25: Cost of Equity | K25: =K22+(K23*K24) -> 0.030286896
B28: Capital Structure | G28: Levered Beta
D30: Current | E30: Target | G30: Comps Median Unlevered Beta | K30: =K17 -> -0.55303345
B31: Total Debt | C31: =E11 -> 8796 | D31: =C31/$C$33 -> 0.014283833 | E31: =I16 -> 0.023332019 | G31: Target Debt /Equity | K31: =E35 -> 0.023889407
B32: Market Capitalization | C32: =F11 -> 607005.1 | D32: =C32/$C$33 -> 0.98571617 | E32: =E33-E31 -> 0.97666798 | G32: Tax Rate | K32: =E23 -> 0.3
B33: Total Capital | C33: =SUM(C31:C32) -> 615801.1 | D33: =C33/$C$33 -> 1 | E33: =D33 -> 1 | G33: Levered Beta | K33: =K30*(1+(1-K32)*K31) -> -0.5622816
B35: Debt/ Equity | D35: =D31/D32 -> 0.014490817 | E35: =E31/E32 -> 0.023889407 | G35: Weighted Average Cost of Capital
B37: Notes: | G37: Cost of Equity | K37: =K25 -> 0.030286896
B38: 1. Tax Rate considered as Marginal Tax Rate for the countary | G38: Equity Weight | K38: =E32 -> 0.97666798
B39: 2. Levered Beta is based on 5 year monthly data
B40: 3. Unlevered beta = Levered Beta/1+(1- Tax Rate)*Debt/ Equity) | G40: Cost of Debt | K40: =E24 -> 0.033105957
B41: 4. Levered beta = Unlevered Beta*1+(1- Tax Rate)*Debt/ Equity) | G41: Debt Weight | K41: =E31 -> 0.023332019
G43: WACC | K43: =(K37*K38)+(K40*K41) -> 0.03035267

Sheet Intrisic Growth
